<?xml version="1.0" encoding="UTF-8"?>
<!-- Generated by org.testng.reporters.JUnitReportReporter -->
<testsuite hostname="AMAC02FP09XQ6LW" failures="12" tests="42" name="calculator.TestCases.Addition" time="96.448" errors="0" timestamp="2022-05-15T19:03:34 EEST" skipped="0">
  <testcase classname="calculator.TestCases.Addition" name="AdditionTwoNumber" time="2.229"/>
  <system-out/>
  <testcase classname="calculator.TestCases.Addition" name="AdditionTwoNumber" time="2.256">
    <failure message="expected [true] but found [false]" type="java.lang.AssertionError">
      <![CDATA[java.lang.AssertionError: expected [true] but found [false]
at org.testng.Assert.fail(Assert.java:99)
at org.testng.Assert.failNotEquals(Assert.java:1037)
at org.testng.Assert.assertTrue(Assert.java:45)
at org.testng.Assert.assertTrue(Assert.java:55)
at calculator.TestCases.Addition.AdditionTwoNumber(Addition.java:30)
at java.base/jdk.internal.reflect.NativeMethodAccessorImpl.invoke0(Native Method)
at java.base/jdk.internal.reflect.NativeMethodAccessorImpl.invoke(NativeMethodAccessorImpl.java:77)
at java.base/jdk.internal.reflect.DelegatingMethodAccessorImpl.invoke(DelegatingMethodAccessorImpl.java:43)
at java.base/java.lang.reflect.Method.invoke(Method.java:568)
at org.testng.internal.MethodInvocationHelper.invokeMethod(MethodInvocationHelper.java:132)
at org.testng.internal.TestInvoker.invokeMethod(TestInvoker.java:599)
at org.testng.internal.TestInvoker.invokeTestMethod(TestInvoker.java:174)
at org.testng.internal.MethodRunner.runInSequence(MethodRunner.java:46)
at org.testng.internal.TestInvoker$MethodInvocationAgent.invoke(TestInvoker.java:822)
at org.testng.internal.TestInvoker.invokeTestMethods(TestInvoker.java:147)
at org.testng.internal.TestMethodWorker.invokeTestMethods(TestMethodWorker.java:146)
at org.testng.internal.TestMethodWorker.run(TestMethodWorker.java:128)
at java.base/java.util.ArrayList.forEach(ArrayList.java:1511)
at org.testng.TestRunner.privateRun(TestRunner.java:764)
at org.testng.TestRunner.run(TestRunner.java:585)
at org.testng.SuiteRunner.runTest(SuiteRunner.java:384)
at org.testng.SuiteRunner.runSequentially(SuiteRunner.java:378)
at org.testng.SuiteRunner.privateRun(SuiteRunner.java:337)
at org.testng.SuiteRunner.run(SuiteRunner.java:286)
at org.testng.SuiteRunnerWorker.runSuite(SuiteRunnerWorker.java:53)
at org.testng.SuiteRunnerWorker.run(SuiteRunnerWorker.java:96)
at org.testng.TestNG.runSuitesSequentially(TestNG.java:1218)
at org.testng.TestNG.runSuitesLocally(TestNG.java:1140)
at org.testng.TestNG.runSuites(TestNG.java:1069)
at org.testng.TestNG.run(TestNG.java:1037)
at org.testng.remote.AbstractRemoteTestNG.run(AbstractRemoteTestNG.java:115)
at org.testng.remote.RemoteTestNG.initAndRun(RemoteTestNG.java:251)
at org.testng.remote.RemoteTestNG.main(RemoteTestNG.java:77)
]]>
    </failure>
  </testcase> <!-- AdditionTwoNumber -->
  <system-out/>
  <testcase classname="calculator.TestCases.Addition" name="AdditionTwoNumber" time="2.213">
    <failure message="expected [true] but found [false]" type="java.lang.AssertionError">
      <![CDATA[java.lang.AssertionError: expected [true] but found [false]
at org.testng.Assert.fail(Assert.java:99)
at org.testng.Assert.failNotEquals(Assert.java:1037)
at org.testng.Assert.assertTrue(Assert.java:45)
at org.testng.Assert.assertTrue(Assert.java:55)
at calculator.TestCases.Addition.AdditionTwoNumber(Addition.java:30)
at jdk.internal.reflect.GeneratedMethodAccessor8.invoke(Unknown Source)
at java.base/jdk.internal.reflect.DelegatingMethodAccessorImpl.invoke(DelegatingMethodAccessorImpl.java:43)
at java.base/java.lang.reflect.Method.invoke(Method.java:568)
at org.testng.internal.MethodInvocationHelper.invokeMethod(MethodInvocationHelper.java:132)
at org.testng.internal.TestInvoker.invokeMethod(TestInvoker.java:599)
at org.testng.internal.TestInvoker.invokeTestMethod(TestInvoker.java:174)
at org.testng.internal.MethodRunner.runInSequence(MethodRunner.java:46)
at org.testng.internal.TestInvoker$MethodInvocationAgent.invoke(TestInvoker.java:822)
at org.testng.internal.TestInvoker.invokeTestMethods(TestInvoker.java:147)
at org.testng.internal.TestMethodWorker.invokeTestMethods(TestMethodWorker.java:146)
at org.testng.internal.TestMethodWorker.run(TestMethodWorker.java:128)
at java.base/java.util.ArrayList.forEach(ArrayList.java:1511)
at org.testng.TestRunner.privateRun(TestRunner.java:764)
at org.testng.TestRunner.run(TestRunner.java:585)
at org.testng.SuiteRunner.runTest(SuiteRunner.java:384)
at org.testng.SuiteRunner.runSequentially(SuiteRunner.java:378)
at org.testng.SuiteRunner.privateRun(SuiteRunner.java:337)
at org.testng.SuiteRunner.run(SuiteRunner.java:286)
at org.testng.SuiteRunnerWorker.runSuite(SuiteRunnerWorker.java:53)
at org.testng.SuiteRunnerWorker.run(SuiteRunnerWorker.java:96)
at org.testng.TestNG.runSuitesSequentially(TestNG.java:1218)
at org.testng.TestNG.runSuitesLocally(TestNG.java:1140)
at org.testng.TestNG.runSuites(TestNG.java:1069)
at org.testng.TestNG.run(TestNG.java:1037)
at org.testng.remote.AbstractRemoteTestNG.run(AbstractRemoteTestNG.java:115)
at org.testng.remote.RemoteTestNG.initAndRun(RemoteTestNG.java:251)
at org.testng.remote.RemoteTestNG.main(RemoteTestNG.java:77)
]]>
    </failure>
  </testcase> <!-- AdditionTwoNumber -->
  <system-out/>
  <testcase classname="calculator.TestCases.Addition" name="AdditionTwoNumber" time="2.255"/>
  <system-out/>
  <testcase classname="calculator.TestCases.Addition" name="AdditionIntegerOnly" time="2.291"/>
  <system-out/>
  <testcase classname="calculator.TestCases.Addition" name="AdditionTwoNumber" time="2.203"/>
  <system-out/>
  <testcase classname="calculator.TestCases.Addition" name="AdditionIntegerOnly" time="2.243"/>
  <system-out/>
  <testcase classname="calculator.TestCases.Addition" name="AdditionIntegerOnly" time="2.237">
    <failure message="expected [true] but found [false]" type="java.lang.AssertionError">
      <![CDATA[java.lang.AssertionError: expected [true] but found [false]
at org.testng.Assert.fail(Assert.java:99)
at org.testng.Assert.failNotEquals(Assert.java:1037)
at org.testng.Assert.assertTrue(Assert.java:45)
at org.testng.Assert.assertTrue(Assert.java:55)
at calculator.TestCases.Addition.AdditionIntegerOnly(Addition.java:58)
at jdk.internal.reflect.GeneratedMethodAccessor7.invoke(Unknown Source)
at java.base/jdk.internal.reflect.DelegatingMethodAccessorImpl.invoke(DelegatingMethodAccessorImpl.java:43)
at java.base/java.lang.reflect.Method.invoke(Method.java:568)
at org.testng.internal.MethodInvocationHelper.invokeMethod(MethodInvocationHelper.java:132)
at org.testng.internal.TestInvoker.invokeMethod(TestInvoker.java:599)
at org.testng.internal.TestInvoker.invokeTestMethod(TestInvoker.java:174)
at org.testng.internal.MethodRunner.runInSequence(MethodRunner.java:46)
at org.testng.internal.TestInvoker$MethodInvocationAgent.invoke(TestInvoker.java:822)
at org.testng.internal.TestInvoker.invokeTestMethods(TestInvoker.java:147)
at org.testng.internal.TestMethodWorker.invokeTestMethods(TestMethodWorker.java:146)
at org.testng.internal.TestMethodWorker.run(TestMethodWorker.java:128)
at java.base/java.util.ArrayList.forEach(ArrayList.java:1511)
at org.testng.TestRunner.privateRun(TestRunner.java:764)
at org.testng.TestRunner.run(TestRunner.java:585)
at org.testng.SuiteRunner.runTest(SuiteRunner.java:384)
at org.testng.SuiteRunner.runSequentially(SuiteRunner.java:378)
at org.testng.SuiteRunner.privateRun(SuiteRunner.java:337)
at org.testng.SuiteRunner.run(SuiteRunner.java:286)
at org.testng.SuiteRunnerWorker.runSuite(SuiteRunnerWorker.java:53)
at org.testng.SuiteRunnerWorker.run(SuiteRunnerWorker.java:96)
at org.testng.TestNG.runSuitesSequentially(TestNG.java:1218)
at org.testng.TestNG.runSuitesLocally(TestNG.java:1140)
at org.testng.TestNG.runSuites(TestNG.java:1069)
at org.testng.TestNG.run(TestNG.java:1037)
at org.testng.remote.AbstractRemoteTestNG.run(AbstractRemoteTestNG.java:115)
at org.testng.remote.RemoteTestNG.initAndRun(RemoteTestNG.java:251)
at org.testng.remote.RemoteTestNG.main(RemoteTestNG.java:77)
]]>
    </failure>
  </testcase> <!-- AdditionIntegerOnly -->
  <system-out/>
  <testcase classname="calculator.TestCases.Addition" name="AdditionIntegerOnly" time="2.357"/>
  <system-out/>
  <testcase classname="calculator.TestCases.Addition" name="AdditionIntegerOnly" time="2.385"/>
  <system-out/>
  <testcase classname="calculator.TestCases.Addition" name="AdditionIntegerOnly" time="2.277">
    <failure message="expected [true] but found [false]" type="java.lang.AssertionError">
      <![CDATA[java.lang.AssertionError: expected [true] but found [false]
at org.testng.Assert.fail(Assert.java:99)
at org.testng.Assert.failNotEquals(Assert.java:1037)
at org.testng.Assert.assertTrue(Assert.java:45)
at org.testng.Assert.assertTrue(Assert.java:55)
at calculator.TestCases.Addition.AdditionIntegerOnly(Addition.java:61)
at java.base/jdk.internal.reflect.NativeMethodAccessorImpl.invoke0(Native Method)
at java.base/jdk.internal.reflect.NativeMethodAccessorImpl.invoke(NativeMethodAccessorImpl.java:77)
at java.base/jdk.internal.reflect.DelegatingMethodAccessorImpl.invoke(DelegatingMethodAccessorImpl.java:43)
at java.base/java.lang.reflect.Method.invoke(Method.java:568)
at org.testng.internal.MethodInvocationHelper.invokeMethod(MethodInvocationHelper.java:132)
at org.testng.internal.TestInvoker.invokeMethod(TestInvoker.java:599)
at org.testng.internal.TestInvoker.invokeTestMethod(TestInvoker.java:174)
at org.testng.internal.MethodRunner.runInSequence(MethodRunner.java:46)
at org.testng.internal.TestInvoker$MethodInvocationAgent.invoke(TestInvoker.java:822)
at org.testng.internal.TestInvoker.invokeTestMethods(TestInvoker.java:147)
at org.testng.internal.TestMethodWorker.invokeTestMethods(TestMethodWorker.java:146)
at org.testng.internal.TestMethodWorker.run(TestMethodWorker.java:128)
at java.base/java.util.ArrayList.forEach(ArrayList.java:1511)
at org.testng.TestRunner.privateRun(TestRunner.java:764)
at org.testng.TestRunner.run(TestRunner.java:585)
at org.testng.SuiteRunner.runTest(SuiteRunner.java:384)
at org.testng.SuiteRunner.runSequentially(SuiteRunner.java:378)
at org.testng.SuiteRunner.privateRun(SuiteRunner.java:337)
at org.testng.SuiteRunner.run(SuiteRunner.java:286)
at org.testng.SuiteRunnerWorker.runSuite(SuiteRunnerWorker.java:53)
at org.testng.SuiteRunnerWorker.run(SuiteRunnerWorker.java:96)
at org.testng.TestNG.runSuitesSequentially(TestNG.java:1218)
at org.testng.TestNG.runSuitesLocally(TestNG.java:1140)
at org.testng.TestNG.runSuites(TestNG.java:1069)
at org.testng.TestNG.run(TestNG.java:1037)
at org.testng.remote.AbstractRemoteTestNG.run(AbstractRemoteTestNG.java:115)
at org.testng.remote.RemoteTestNG.initAndRun(RemoteTestNG.java:251)
at org.testng.remote.RemoteTestNG.main(RemoteTestNG.java:77)
]]>
    </failure>
  </testcase> <!-- AdditionIntegerOnly -->
  <system-out/>
  <testcase classname="calculator.TestCases.Addition" name="AdditionTwoNumber" time="2.204"/>
  <system-out/>
  <testcase classname="calculator.TestCases.Addition" name="AdditionIntegerOnly" time="2.306"/>
  <system-out/>
  <testcase classname="calculator.TestCases.Addition" name="AdditionIntegerOnly" time="2.283"/>
  <system-out/>
  <testcase classname="calculator.TestCases.Addition" name="AdditionIntegerOnly" time="2.586">
    <failure message="expected [true] but found [false]" type="java.lang.AssertionError">
      <![CDATA[java.lang.AssertionError: expected [true] but found [false]
at org.testng.Assert.fail(Assert.java:99)
at org.testng.Assert.failNotEquals(Assert.java:1037)
at org.testng.Assert.assertTrue(Assert.java:45)
at org.testng.Assert.assertTrue(Assert.java:55)
at calculator.TestCases.Addition.AdditionIntegerOnly(Addition.java:61)
at java.base/jdk.internal.reflect.NativeMethodAccessorImpl.invoke0(Native Method)
at java.base/jdk.internal.reflect.NativeMethodAccessorImpl.invoke(NativeMethodAccessorImpl.java:77)
at java.base/jdk.internal.reflect.DelegatingMethodAccessorImpl.invoke(DelegatingMethodAccessorImpl.java:43)
at java.base/java.lang.reflect.Method.invoke(Method.java:568)
at org.testng.internal.MethodInvocationHelper.invokeMethod(MethodInvocationHelper.java:132)
at org.testng.internal.TestInvoker.invokeMethod(TestInvoker.java:599)
at org.testng.internal.TestInvoker.invokeTestMethod(TestInvoker.java:174)
at org.testng.internal.MethodRunner.runInSequence(MethodRunner.java:46)
at org.testng.internal.TestInvoker$MethodInvocationAgent.invoke(TestInvoker.java:822)
at org.testng.internal.TestInvoker.invokeTestMethods(TestInvoker.java:147)
at org.testng.internal.TestMethodWorker.invokeTestMethods(TestMethodWorker.java:146)
at org.testng.internal.TestMethodWorker.run(TestMethodWorker.java:128)
at java.base/java.util.ArrayList.forEach(ArrayList.java:1511)
at org.testng.TestRunner.privateRun(TestRunner.java:764)
at org.testng.TestRunner.run(TestRunner.java:585)
at org.testng.SuiteRunner.runTest(SuiteRunner.java:384)
at org.testng.SuiteRunner.runSequentially(SuiteRunner.java:378)
at org.testng.SuiteRunner.privateRun(SuiteRunner.java:337)
at org.testng.SuiteRunner.run(SuiteRunner.java:286)
at org.testng.SuiteRunnerWorker.runSuite(SuiteRunnerWorker.java:53)
at org.testng.SuiteRunnerWorker.run(SuiteRunnerWorker.java:96)
at org.testng.TestNG.runSuitesSequentially(TestNG.java:1218)
at org.testng.TestNG.runSuitesLocally(TestNG.java:1140)
at org.testng.TestNG.runSuites(TestNG.java:1069)
at org.testng.TestNG.run(TestNG.java:1037)
at org.testng.remote.AbstractRemoteTestNG.run(AbstractRemoteTestNG.java:115)
at org.testng.remote.RemoteTestNG.initAndRun(RemoteTestNG.java:251)
at org.testng.remote.RemoteTestNG.main(RemoteTestNG.java:77)
]]>
    </failure>
  </testcase> <!-- AdditionIntegerOnly -->
  <system-out/>
  <testcase classname="calculator.TestCases.Addition" name="AdditionTwoNumber" time="2.213"/>
  <system-out/>
  <testcase classname="calculator.TestCases.Addition" name="AdditionTwoNumber" time="2.210">
    <failure message="expected [true] but found [false]" type="java.lang.AssertionError">
      <![CDATA[java.lang.AssertionError: expected [true] but found [false]
at org.testng.Assert.fail(Assert.java:99)
at org.testng.Assert.failNotEquals(Assert.java:1037)
at org.testng.Assert.assertTrue(Assert.java:45)
at org.testng.Assert.assertTrue(Assert.java:55)
at calculator.TestCases.Addition.AdditionTwoNumber(Addition.java:30)
at java.base/jdk.internal.reflect.NativeMethodAccessorImpl.invoke0(Native Method)
at java.base/jdk.internal.reflect.NativeMethodAccessorImpl.invoke(NativeMethodAccessorImpl.java:77)
at java.base/jdk.internal.reflect.DelegatingMethodAccessorImpl.invoke(DelegatingMethodAccessorImpl.java:43)
at java.base/java.lang.reflect.Method.invoke(Method.java:568)
at org.testng.internal.MethodInvocationHelper.invokeMethod(MethodInvocationHelper.java:132)
at org.testng.internal.TestInvoker.invokeMethod(TestInvoker.java:599)
at org.testng.internal.TestInvoker.invokeTestMethod(TestInvoker.java:174)
at org.testng.internal.MethodRunner.runInSequence(MethodRunner.java:46)
at org.testng.internal.TestInvoker$MethodInvocationAgent.invoke(TestInvoker.java:822)
at org.testng.internal.TestInvoker.invokeTestMethods(TestInvoker.java:147)
at org.testng.internal.TestMethodWorker.invokeTestMethods(TestMethodWorker.java:146)
at org.testng.internal.TestMethodWorker.run(TestMethodWorker.java:128)
at java.base/java.util.ArrayList.forEach(ArrayList.java:1511)
at org.testng.TestRunner.privateRun(TestRunner.java:764)
at org.testng.TestRunner.run(TestRunner.java:585)
at org.testng.SuiteRunner.runTest(SuiteRunner.java:384)
at org.testng.SuiteRunner.runSequentially(SuiteRunner.java:378)
at org.testng.SuiteRunner.privateRun(SuiteRunner.java:337)
at org.testng.SuiteRunner.run(SuiteRunner.java:286)
at org.testng.SuiteRunnerWorker.runSuite(SuiteRunnerWorker.java:53)
at org.testng.SuiteRunnerWorker.run(SuiteRunnerWorker.java:96)
at org.testng.TestNG.runSuitesSequentially(TestNG.java:1218)
at org.testng.TestNG.runSuitesLocally(TestNG.java:1140)
at org.testng.TestNG.runSuites(TestNG.java:1069)
at org.testng.TestNG.run(TestNG.java:1037)
at org.testng.remote.AbstractRemoteTestNG.run(AbstractRemoteTestNG.java:115)
at org.testng.remote.RemoteTestNG.initAndRun(RemoteTestNG.java:251)
at org.testng.remote.RemoteTestNG.main(RemoteTestNG.java:77)
]]>
    </failure>
  </testcase> <!-- AdditionTwoNumber -->
  <system-out/>
  <testcase classname="calculator.TestCases.Addition" name="AdditionIntegerOnly" time="2.261"/>
  <system-out/>
  <testcase classname="calculator.TestCases.Addition" name="AdditionIntegerOnly" time="2.613"/>
  <system-out/>
  <testcase classname="calculator.TestCases.Addition" name="AdditionTwoNumber" time="2.235"/>
  <system-out/>
  <testcase classname="calculator.TestCases.Addition" name="AdditionIntegerOnly" time="2.220"/>
  <system-out/>
  <testcase classname="calculator.TestCases.Addition" name="AdditionTwoNumber" time="2.208">
    <failure message="expected [true] but found [false]" type="java.lang.AssertionError">
      <![CDATA[java.lang.AssertionError: expected [true] but found [false]
at org.testng.Assert.fail(Assert.java:99)
at org.testng.Assert.failNotEquals(Assert.java:1037)
at org.testng.Assert.assertTrue(Assert.java:45)
at org.testng.Assert.assertTrue(Assert.java:55)
at calculator.TestCases.Addition.AdditionTwoNumber(Addition.java:27)
at jdk.internal.reflect.GeneratedMethodAccessor8.invoke(Unknown Source)
at java.base/jdk.internal.reflect.DelegatingMethodAccessorImpl.invoke(DelegatingMethodAccessorImpl.java:43)
at java.base/java.lang.reflect.Method.invoke(Method.java:568)
at org.testng.internal.MethodInvocationHelper.invokeMethod(MethodInvocationHelper.java:132)
at org.testng.internal.TestInvoker.invokeMethod(TestInvoker.java:599)
at org.testng.internal.TestInvoker.invokeTestMethod(TestInvoker.java:174)
at org.testng.internal.MethodRunner.runInSequence(MethodRunner.java:46)
at org.testng.internal.TestInvoker$MethodInvocationAgent.invoke(TestInvoker.java:822)
at org.testng.internal.TestInvoker.invokeTestMethods(TestInvoker.java:147)
at org.testng.internal.TestMethodWorker.invokeTestMethods(TestMethodWorker.java:146)
at org.testng.internal.TestMethodWorker.run(TestMethodWorker.java:128)
at java.base/java.util.ArrayList.forEach(ArrayList.java:1511)
at org.testng.TestRunner.privateRun(TestRunner.java:764)
at org.testng.TestRunner.run(TestRunner.java:585)
at org.testng.SuiteRunner.runTest(SuiteRunner.java:384)
at org.testng.SuiteRunner.runSequentially(SuiteRunner.java:378)
at org.testng.SuiteRunner.privateRun(SuiteRunner.java:337)
at org.testng.SuiteRunner.run(SuiteRunner.java:286)
at org.testng.SuiteRunnerWorker.runSuite(SuiteRunnerWorker.java:53)
at org.testng.SuiteRunnerWorker.run(SuiteRunnerWorker.java:96)
at org.testng.TestNG.runSuitesSequentially(TestNG.java:1218)
at org.testng.TestNG.runSuitesLocally(TestNG.java:1140)
at org.testng.TestNG.runSuites(TestNG.java:1069)
at org.testng.TestNG.run(TestNG.java:1037)
at org.testng.remote.AbstractRemoteTestNG.run(AbstractRemoteTestNG.java:115)
at org.testng.remote.RemoteTestNG.initAndRun(RemoteTestNG.java:251)
at org.testng.remote.RemoteTestNG.main(RemoteTestNG.java:77)
]]>
    </failure>
  </testcase> <!-- AdditionTwoNumber -->
  <system-out/>
  <testcase classname="calculator.TestCases.Addition" name="AdditionIntegerOnly" time="2.249"/>
  <system-out/>
  <testcase classname="calculator.TestCases.Addition" name="AdditionIntegerOnly" time="2.245"/>
  <system-out/>
  <testcase classname="calculator.TestCases.Addition" name="AdditionTwoNumber" time="2.220"/>
  <system-out/>
  <testcase classname="calculator.TestCases.Addition" name="AdditionTwoNumber" time="2.254"/>
  <system-out/>
  <testcase classname="calculator.TestCases.Addition" name="AdditionIntegerOnly" time="2.321"/>
  <system-out/>
  <testcase classname="calculator.TestCases.Addition" name="AdditionTwoNumber" time="2.201"/>
  <system-out/>
  <testcase classname="calculator.TestCases.Addition" name="AdditionTwoNumber" time="2.221"/>
  <system-out/>
  <testcase classname="calculator.TestCases.Addition" name="AdditionIntegerOnly" time="2.258">
    <failure message="expected [true] but found [false]" type="java.lang.AssertionError">
      <![CDATA[java.lang.AssertionError: expected [true] but found [false]
at org.testng.Assert.fail(Assert.java:99)
at org.testng.Assert.failNotEquals(Assert.java:1037)
at org.testng.Assert.assertTrue(Assert.java:45)
at org.testng.Assert.assertTrue(Assert.java:55)
at calculator.TestCases.Addition.AdditionIntegerOnly(Addition.java:61)
at jdk.internal.reflect.GeneratedMethodAccessor7.invoke(Unknown Source)
at java.base/jdk.internal.reflect.DelegatingMethodAccessorImpl.invoke(DelegatingMethodAccessorImpl.java:43)
at java.base/java.lang.reflect.Method.invoke(Method.java:568)
at org.testng.internal.MethodInvocationHelper.invokeMethod(MethodInvocationHelper.java:132)
at org.testng.internal.TestInvoker.invokeMethod(TestInvoker.java:599)
at org.testng.internal.TestInvoker.invokeTestMethod(TestInvoker.java:174)
at org.testng.internal.MethodRunner.runInSequence(MethodRunner.java:46)
at org.testng.internal.TestInvoker$MethodInvocationAgent.invoke(TestInvoker.java:822)
at org.testng.internal.TestInvoker.invokeTestMethods(TestInvoker.java:147)
at org.testng.internal.TestMethodWorker.invokeTestMethods(TestMethodWorker.java:146)
at org.testng.internal.TestMethodWorker.run(TestMethodWorker.java:128)
at java.base/java.util.ArrayList.forEach(ArrayList.java:1511)
at org.testng.TestRunner.privateRun(TestRunner.java:764)
at org.testng.TestRunner.run(TestRunner.java:585)
at org.testng.SuiteRunner.runTest(SuiteRunner.java:384)
at org.testng.SuiteRunner.runSequentially(SuiteRunner.java:378)
at org.testng.SuiteRunner.privateRun(SuiteRunner.java:337)
at org.testng.SuiteRunner.run(SuiteRunner.java:286)
at org.testng.SuiteRunnerWorker.runSuite(SuiteRunnerWorker.java:53)
at org.testng.SuiteRunnerWorker.run(SuiteRunnerWorker.java:96)
at org.testng.TestNG.runSuitesSequentially(TestNG.java:1218)
at org.testng.TestNG.runSuitesLocally(TestNG.java:1140)
at org.testng.TestNG.runSuites(TestNG.java:1069)
at org.testng.TestNG.run(TestNG.java:1037)
at org.testng.remote.AbstractRemoteTestNG.run(AbstractRemoteTestNG.java:115)
at org.testng.remote.RemoteTestNG.initAndRun(RemoteTestNG.java:251)
at org.testng.remote.RemoteTestNG.main(RemoteTestNG.java:77)
]]>
    </failure>
  </testcase> <!-- AdditionIntegerOnly -->
  <system-out/>
  <testcase classname="calculator.TestCases.Addition" name="AdditionIntegerOnly" time="2.265">
    <failure message="expected [true] but found [false]" type="java.lang.AssertionError">
      <![CDATA[java.lang.AssertionError: expected [true] but found [false]
at org.testng.Assert.fail(Assert.java:99)
at org.testng.Assert.failNotEquals(Assert.java:1037)
at org.testng.Assert.assertTrue(Assert.java:45)
at org.testng.Assert.assertTrue(Assert.java:55)
at calculator.TestCases.Addition.AdditionIntegerOnly(Addition.java:58)
at jdk.internal.reflect.GeneratedMethodAccessor7.invoke(Unknown Source)
at java.base/jdk.internal.reflect.DelegatingMethodAccessorImpl.invoke(DelegatingMethodAccessorImpl.java:43)
at java.base/java.lang.reflect.Method.invoke(Method.java:568)
at org.testng.internal.MethodInvocationHelper.invokeMethod(MethodInvocationHelper.java:132)
at org.testng.internal.TestInvoker.invokeMethod(TestInvoker.java:599)
at org.testng.internal.TestInvoker.invokeTestMethod(TestInvoker.java:174)
at org.testng.internal.MethodRunner.runInSequence(MethodRunner.java:46)
at org.testng.internal.TestInvoker$MethodInvocationAgent.invoke(TestInvoker.java:822)
at org.testng.internal.TestInvoker.invokeTestMethods(TestInvoker.java:147)
at org.testng.internal.TestMethodWorker.invokeTestMethods(TestMethodWorker.java:146)
at org.testng.internal.TestMethodWorker.run(TestMethodWorker.java:128)
at java.base/java.util.ArrayList.forEach(ArrayList.java:1511)
at org.testng.TestRunner.privateRun(TestRunner.java:764)
at org.testng.TestRunner.run(TestRunner.java:585)
at org.testng.SuiteRunner.runTest(SuiteRunner.java:384)
at org.testng.SuiteRunner.runSequentially(SuiteRunner.java:378)
at org.testng.SuiteRunner.privateRun(SuiteRunner.java:337)
at org.testng.SuiteRunner.run(SuiteRunner.java:286)
at org.testng.SuiteRunnerWorker.runSuite(SuiteRunnerWorker.java:53)
at org.testng.SuiteRunnerWorker.run(SuiteRunnerWorker.java:96)
at org.testng.TestNG.runSuitesSequentially(TestNG.java:1218)
at org.testng.TestNG.runSuitesLocally(TestNG.java:1140)
at org.testng.TestNG.runSuites(TestNG.java:1069)
at org.testng.TestNG.run(TestNG.java:1037)
at org.testng.remote.AbstractRemoteTestNG.run(AbstractRemoteTestNG.java:115)
at org.testng.remote.RemoteTestNG.initAndRun(RemoteTestNG.java:251)
at org.testng.remote.RemoteTestNG.main(RemoteTestNG.java:77)
]]>
    </failure>
  </testcase> <!-- AdditionIntegerOnly -->
  <system-out/>
  <testcase classname="calculator.TestCases.Addition" name="AdditionIntegerOnly" time="3.166"/>
  <system-out/>
  <testcase classname="calculator.TestCases.Addition" name="AdditionTwoNumber" time="2.212">
    <failure message="expected [true] but found [false]" type="java.lang.AssertionError">
      <![CDATA[java.lang.AssertionError: expected [true] but found [false]
at org.testng.Assert.fail(Assert.java:99)
at org.testng.Assert.failNotEquals(Assert.java:1037)
at org.testng.Assert.assertTrue(Assert.java:45)
at org.testng.Assert.assertTrue(Assert.java:55)
at calculator.TestCases.Addition.AdditionTwoNumber(Addition.java:27)
at java.base/jdk.internal.reflect.NativeMethodAccessorImpl.invoke0(Native Method)
at java.base/jdk.internal.reflect.NativeMethodAccessorImpl.invoke(NativeMethodAccessorImpl.java:77)
at java.base/jdk.internal.reflect.DelegatingMethodAccessorImpl.invoke(DelegatingMethodAccessorImpl.java:43)
at java.base/java.lang.reflect.Method.invoke(Method.java:568)
at org.testng.internal.MethodInvocationHelper.invokeMethod(MethodInvocationHelper.java:132)
at org.testng.internal.TestInvoker.invokeMethod(TestInvoker.java:599)
at org.testng.internal.TestInvoker.invokeTestMethod(TestInvoker.java:174)
at org.testng.internal.MethodRunner.runInSequence(MethodRunner.java:46)
at org.testng.internal.TestInvoker$MethodInvocationAgent.invoke(TestInvoker.java:822)
at org.testng.internal.TestInvoker.invokeTestMethods(TestInvoker.java:147)
at org.testng.internal.TestMethodWorker.invokeTestMethods(TestMethodWorker.java:146)
at org.testng.internal.TestMethodWorker.run(TestMethodWorker.java:128)
at java.base/java.util.ArrayList.forEach(ArrayList.java:1511)
at org.testng.TestRunner.privateRun(TestRunner.java:764)
at org.testng.TestRunner.run(TestRunner.java:585)
at org.testng.SuiteRunner.runTest(SuiteRunner.java:384)
at org.testng.SuiteRunner.runSequentially(SuiteRunner.java:378)
at org.testng.SuiteRunner.privateRun(SuiteRunner.java:337)
at org.testng.SuiteRunner.run(SuiteRunner.java:286)
at org.testng.SuiteRunnerWorker.runSuite(SuiteRunnerWorker.java:53)
at org.testng.SuiteRunnerWorker.run(SuiteRunnerWorker.java:96)
at org.testng.TestNG.runSuitesSequentially(TestNG.java:1218)
at org.testng.TestNG.runSuitesLocally(TestNG.java:1140)
at org.testng.TestNG.runSuites(TestNG.java:1069)
at org.testng.TestNG.run(TestNG.java:1037)
at org.testng.remote.AbstractRemoteTestNG.run(AbstractRemoteTestNG.java:115)
at org.testng.remote.RemoteTestNG.initAndRun(RemoteTestNG.java:251)
at org.testng.remote.RemoteTestNG.main(RemoteTestNG.java:77)
]]>
    </failure>
  </testcase> <!-- AdditionTwoNumber -->
  <system-out/>
  <testcase classname="calculator.TestCases.Addition" name="AdditionTwoNumber" time="2.199">
    <failure message="expected [true] but found [false]" type="java.lang.AssertionError">
      <![CDATA[java.lang.AssertionError: expected [true] but found [false]
at org.testng.Assert.fail(Assert.java:99)
at org.testng.Assert.failNotEquals(Assert.java:1037)
at org.testng.Assert.assertTrue(Assert.java:45)
at org.testng.Assert.assertTrue(Assert.java:55)
at calculator.TestCases.Addition.AdditionTwoNumber(Addition.java:27)
at java.base/jdk.internal.reflect.NativeMethodAccessorImpl.invoke0(Native Method)
at java.base/jdk.internal.reflect.NativeMethodAccessorImpl.invoke(NativeMethodAccessorImpl.java:77)
at java.base/jdk.internal.reflect.DelegatingMethodAccessorImpl.invoke(DelegatingMethodAccessorImpl.java:43)
at java.base/java.lang.reflect.Method.invoke(Method.java:568)
at org.testng.internal.MethodInvocationHelper.invokeMethod(MethodInvocationHelper.java:132)
at org.testng.internal.TestInvoker.invokeMethod(TestInvoker.java:599)
at org.testng.internal.TestInvoker.invokeTestMethod(TestInvoker.java:174)
at org.testng.internal.MethodRunner.runInSequence(MethodRunner.java:46)
at org.testng.internal.TestInvoker$MethodInvocationAgent.invoke(TestInvoker.java:822)
at org.testng.internal.TestInvoker.invokeTestMethods(TestInvoker.java:147)
at org.testng.internal.TestMethodWorker.invokeTestMethods(TestMethodWorker.java:146)
at org.testng.internal.TestMethodWorker.run(TestMethodWorker.java:128)
at java.base/java.util.ArrayList.forEach(ArrayList.java:1511)
at org.testng.TestRunner.privateRun(TestRunner.java:764)
at org.testng.TestRunner.run(TestRunner.java:585)
at org.testng.SuiteRunner.runTest(SuiteRunner.java:384)
at org.testng.SuiteRunner.runSequentially(SuiteRunner.java:378)
at org.testng.SuiteRunner.privateRun(SuiteRunner.java:337)
at org.testng.SuiteRunner.run(SuiteRunner.java:286)
at org.testng.SuiteRunnerWorker.runSuite(SuiteRunnerWorker.java:53)
at org.testng.SuiteRunnerWorker.run(SuiteRunnerWorker.java:96)
at org.testng.TestNG.runSuitesSequentially(TestNG.java:1218)
at org.testng.TestNG.runSuitesLocally(TestNG.java:1140)
at org.testng.TestNG.runSuites(TestNG.java:1069)
at org.testng.TestNG.run(TestNG.java:1037)
at org.testng.remote.AbstractRemoteTestNG.run(AbstractRemoteTestNG.java:115)
at org.testng.remote.RemoteTestNG.initAndRun(RemoteTestNG.java:251)
at org.testng.remote.RemoteTestNG.main(RemoteTestNG.java:77)
]]>
    </failure>
  </testcase> <!-- AdditionTwoNumber -->
  <system-out/>
  <testcase classname="calculator.TestCases.Addition" name="AdditionTwoNumber" time="2.219"/>
  <system-out/>
  <testcase classname="calculator.TestCases.Addition" name="AdditionTwoNumber" time="2.254"/>
  <system-out/>
  <testcase classname="calculator.TestCases.Addition" name="AdditionTwoNumber" time="2.237"/>
  <system-out/>
  <testcase classname="calculator.TestCases.Addition" name="AdditionTwoNumber" time="2.204"/>
  <system-out/>
  <testcase classname="calculator.TestCases.Addition" name="AdditionIntegerOnly" time="2.373">
    <failure message="expected [true] but found [false]" type="java.lang.AssertionError">
      <![CDATA[java.lang.AssertionError: expected [true] but found [false]
at org.testng.Assert.fail(Assert.java:99)
at org.testng.Assert.failNotEquals(Assert.java:1037)
at org.testng.Assert.assertTrue(Assert.java:45)
at org.testng.Assert.assertTrue(Assert.java:55)
at calculator.TestCases.Addition.AdditionIntegerOnly(Addition.java:58)
at java.base/jdk.internal.reflect.NativeMethodAccessorImpl.invoke0(Native Method)
at java.base/jdk.internal.reflect.NativeMethodAccessorImpl.invoke(NativeMethodAccessorImpl.java:77)
at java.base/jdk.internal.reflect.DelegatingMethodAccessorImpl.invoke(DelegatingMethodAccessorImpl.java:43)
at java.base/java.lang.reflect.Method.invoke(Method.java:568)
at org.testng.internal.MethodInvocationHelper.invokeMethod(MethodInvocationHelper.java:132)
at org.testng.internal.TestInvoker.invokeMethod(TestInvoker.java:599)
at org.testng.internal.TestInvoker.invokeTestMethod(TestInvoker.java:174)
at org.testng.internal.MethodRunner.runInSequence(MethodRunner.java:46)
at org.testng.internal.TestInvoker$MethodInvocationAgent.invoke(TestInvoker.java:822)
at org.testng.internal.TestInvoker.invokeTestMethods(TestInvoker.java:147)
at org.testng.internal.TestMethodWorker.invokeTestMethods(TestMethodWorker.java:146)
at org.testng.internal.TestMethodWorker.run(TestMethodWorker.java:128)
at java.base/java.util.ArrayList.forEach(ArrayList.java:1511)
at org.testng.TestRunner.privateRun(TestRunner.java:764)
at org.testng.TestRunner.run(TestRunner.java:585)
at org.testng.SuiteRunner.runTest(SuiteRunner.java:384)
at org.testng.SuiteRunner.runSequentially(SuiteRunner.java:378)
at org.testng.SuiteRunner.privateRun(SuiteRunner.java:337)
at org.testng.SuiteRunner.run(SuiteRunner.java:286)
at org.testng.SuiteRunnerWorker.runSuite(SuiteRunnerWorker.java:53)
at org.testng.SuiteRunnerWorker.run(SuiteRunnerWorker.java:96)
at org.testng.TestNG.runSuitesSequentially(TestNG.java:1218)
at org.testng.TestNG.runSuitesLocally(TestNG.java:1140)
at org.testng.TestNG.runSuites(TestNG.java:1069)
at org.testng.TestNG.run(TestNG.java:1037)
at org.testng.remote.AbstractRemoteTestNG.run(AbstractRemoteTestNG.java:115)
at org.testng.remote.RemoteTestNG.initAndRun(RemoteTestNG.java:251)
at org.testng.remote.RemoteTestNG.main(RemoteTestNG.java:77)
]]>
    </failure>
  </testcase> <!-- AdditionIntegerOnly -->
  <system-out/>
  <testcase classname="calculator.TestCases.Addition" name="AdditionTwoNumber" time="2.187"/>
  <system-out/>
  <testcase classname="calculator.TestCases.Addition" name="AdditionIntegerOnly" time="2.364"/>
  <system-out/>
  <testcase classname="calculator.TestCases.Addition" name="AdditionIntegerOnly" time="2.514"/>
  <system-out/>
</testsuite> <!-- calculator.TestCases.Addition -->
